<?xml version="1.0"?>
<robot name="GoPiGo3">

  <link name="base_link">
    <visual>
      <geometry>
        <cylinder length="0.01" radius="0.075"/>
      </geometry>
      <origin rpy="0 0 -1.57" xyz="0 0 0.035"/>
    </visual>
    <collision>
      <geometry>
        <cylinder length="0.01" radius="0.075"/>
      </geometry>
      <origin rpy="0 0 0" xyz="0 0 0.035"/>
    </collision>
    <!-- <inertial>
      <mass value="1.0"/>
      <inertia ixx="1.0" ixy="0.0" ixz="0.0" iyy="1.0" iyz="0.0" izz="1.0"/>
      <origin rpy="0 0 0" xyz="-0.0375 0.0 0"/>
    </inertial> -->
  </link>

  <link name="camera_link">
    <visual>
      <geometry>
        <box size="0.05 0.08 0.007"/>
      </geometry>
      <origin rpy="0 0 0" xyz="0 0 0"/>
    </visual>
    <collision>
      <geometry>
        <box size="0.05 0.07 0.007"/>
      </geometry>
      <origin rpy="0 0 0" xyz="0 0 0"/>
    </collision>
    <inertial>
      <mass value="0.000005"/>
      <inertia ixx="1.0" ixy="0.0" ixz="0.0" iyy="1.0" iyz="0.0" izz="1.0"/>
      <!-- <origin rpy="0 0 0" xyz="-0.0375 0.0 0"/> -->
    </inertial>
  </link>

  <!-- http://gazebosim.org/tutorials?tut=camera_distortion  -->
  
  <gazebo reference="camera_link">
    <sensor type="camera" name="camera1">
      <update_rate>100</update_rate>
      <camera name="head">
        <pose>0 0 0 0 -1.57 1.57</pose>
        <horizontal_fov>0.915</horizontal_fov>
        <image>
          <width>320</width>
          <height>240</height>
          <format>R8G8B8</format>
        </image>
        <distortion>
          <k1>0.080938</k1>
          <k2>-0.257429</k2>
          <k3>0.000000</k3>
          <t1>-0.002955</t1>
          <t2>0.003629</t2>
        </distortion>
      </camera>
      <plugin name="camera_controller" filename="libgazebo_ros_camera.so">
        <alwaysOn>true</alwaysOn>
        <updateRate>0.0</updateRate>
        <cameraName>gpg</cameraName>
        <imageTopicName>image</imageTopicName>
        <cameraInfoTopicName>camera_info</cameraInfoTopicName>
        <frameName>camera_link</frameName>
        <distortionK1>0.080938</distortionK1>
        <distortionK2>-0.257429</distortionK2>
        <distortionK3>0.000000</distortionK3>
        <distortionT1>-0.002955</distortionT1>
        <distortionT2>0.003629</distortionT2>
      </plugin>
    </sensor>
  </gazebo>

  <link name="left_wheel">
    <visual>
      <geometry>
        <cylinder length="0.015" radius="0.0375"/>
      </geometry>
      <origin rpy="0 1.57075 1.57075" xyz="0 0 0"/>
    </visual>
    <collision>
      <geometry>
        <cylinder length="0.015" radius="0.0375"/>
      </geometry>
      <origin rpy="0 1.57075 1.57075" xyz="0 0 0"/>
    </collision>
    <inertial>
      <mass value="2"/>
      <inertia ixx="1.0" ixy="0.0" ixz="0.0" iyy="1.0" iyz="0.0" izz="1.0"/>
      <!-- <origin rpy="0 0 0" xyz="-0.1 0.0 0"/> -->
    </inertial>
  </link>

  <link name="right_wheel">
    <visual>
      <geometry>
        <cylinder length="0.015" radius="0.0375"/>
      </geometry>
      <origin rpy="0 1.57075 1.57075" xyz="0 0 0"/>
    </visual>
    <collision>
      <geometry>
        <cylinder length="0.015" radius="0.0375"/>
      </geometry>
      <origin rpy="0 1.57075 1.57075" xyz="0 0 0"/>
    </collision>
    <inertial>
      <mass value="2"/>
      <inertia ixx="1.0" ixy="0.0" ixz="0.0" iyy="1.0" iyz="0.0" izz="1.0"/>
      <!-- <origin rpy="0 0 0" xyz="-0.1 0.0 0"/> -->
    </inertial>
  </link>

  <link name="counter_weight">
    <visual>
      <geometry>
        <sphere radius="0.02"/>
      </geometry>
      <origin rpy="0 0 0" xyz="0 0 0"/>
    </visual>
    <collision>
      <geometry>
        <sphere radius="0.02"/>
      </geometry>
      <origin rpy="0 0 0" xyz="0 0 0"/>
    </collision>
    <inertial>
      <mass value="3"/>
      <inertia ixx="1.0" ixy="0.0" ixz="0.0" iyy="1.0" iyz="0.0" izz="1.0"/>
    </inertial>
  </link>

  <joint name="camera_link_to_base_link" type="revolute">
    <axis xyz="0 -1 0"/>
    <limit effort="1000.0" lower="-25.00" upper="25.00" velocity="1.0"/>
    <origin rpy="-1.57075 0 -1.57075 " xyz="0.075 0 0.085"/>
    <parent link="base_link"/>
    <child link="camera_link"/>
  </joint>

  <transmission name="servo">
    <type>transmission_interface/SimpleTransmission</type>
    <actuator name="servo_motor">
      <mechanicalReduction>1</mechanicalReduction>
    </actuator>
    <joint name="camera_link_to_base_link">
      <hardwareInterface>hardware_interface/VelocityJointInterface</hardwareInterface>
    </joint>
  </transmission>

  <joint name="left_wheel_to_base_link" type="continuous">
    <parent link="base_link"/>
    <child link="left_wheel"/>
    <axis xyz="0 1 0"/>
    <origin xyz="0 0.075 0.035"/>
  </joint>

  <transmission name="left_wheel_trans">
    <type>transmission_interface/SimpleTransmission</type>
    <actuator name="$left_wheel_motor">
      <mechanicalReduction>1</mechanicalReduction>
    </actuator>
    <joint name="left_wheel_to_base_link">
      <hardwareInterface>hardware_interface/VelocityJointInterface</hardwareInterface>
    </joint>
  </transmission>

  <joint name="right_wheel_to_base_link" type="continuous">
    <parent link="base_link"/>
    <child link="right_wheel"/>
    <axis xyz="0 1 0"/>
    <origin xyz="0 -0.075 0.035"/>
  </joint>

  <transmission name="right_wheel_trans">
    <type>transmission_interface/SimpleTransmission</type>
    <actuator name="$right_wheel_motor">
      <mechanicalReduction>1</mechanicalReduction>
    </actuator>
    <joint name="right_wheel_to_base_link">
      <hardwareInterface>hardware_interface/VelocityJointInterface</hardwareInterface>
    </joint>
  </transmission>

  <joint name="ball" type="fixed">
    <parent link="base_link"/>
    <child link="counter_weight"/>
    <origin xyz="-0.06 0 0.0175"/>
  </joint>

  <gazebo reference="right_wheel">
    <material>Gazebo/Black</material>
    <mu1>1000000</mu1>
    <mu2>1000000</mu2>
  </gazebo>

  <gazebo reference="left_wheel">
    <material>Gazebo/Black</material>
    <mu1>1000000</mu1>
    <mu2>1000000</mu2>
  </gazebo>

  <gazebo reference="counter_weight">
    <material>Gazebo/Blue</material>
    <mu1>0</mu1>
    <mu2>0</mu2>
  </gazebo>

  <gazebo>
    <plugin name="gazebo_ros_control" filename="libgazebo_ros_control.so">
      <robotNamespace>/gpg</robotNamespace>
    </plugin>
  </gazebo>

</robot>
